Workbook
Name 範囲１: #REF!

Sheet Cover
A1: Cover
O5: #003e83
O6: #0085f0
O7: #2cdcff
D12: Project Management Plan
E16: Projec Code | F16: P001 | H16: System ID
E17: Project Name | F17: Truyenthieu | H17: System Name
E18: Project Manager | F18: DuongNH | H18: Updated Date | I18: 46219
F21: PM | G21: BU Review | H21: Sale review | I21: Approve
E22: Name | F22: Nguyễn Hoàng Dương
E23: Role | F23: PM
E24: Date | F24: 46219

Sheet Page Revision History
D1: REVISION HISTORY | L1: Mã số: BM03-QT-OP-01
L2: Ngày hiệu lực: 10/09/2025
L3: Lần ban hành: 02
B6: # | C6: Last Edited Date | D6: Change Details | G6: Reason | H6: Version | J6: Creator by | K6: Approver by | L6: Remark
B7: 1 | C7: 46219 | D7: Tạo mới | G7: Tạo mới | H7: 1.0 | J7: DuongNH | K7: DuongNH
B8: 2
B9: 3
B10: 4
B11: 5
B12: 6
B13: 7
B14: 8
B15: 9
B16: 10
B17: 11
B18: 12
B19: 13
... B21: 15

Sheet 0. Tasklist
D1: Project Plan Task List | G1: ='Page Revision History'!L1 -> Mã số: BM03-QT-OP-01
G2: ='Page Revision History'!L2 -> Ngày hiệu lực: 10/09/2025
G3: ='Page Revision History'!L3 -> Lần ban hành: 02
B5: No | C5: Task | D5: PIC | E5: Purpose | F5: Note | H5: Status
B6: 1 | C6: 1. Project Information | D6: PM | E6: 1. Project Information 2. Project Scope 3. Project deliverales 4. Project milestone | H6: Open
B7: 2 | C7: 2. Role & Team | D7: PM | E7: 1. Project Roles 2. Responsibility Matrix (RACI Matrix) 3. Team | H7: Open
B8: 3 | C8: 3.Configuration Plan | D8: PM | E8: 1. Folder Configuration/Folder Structure 2. File/Document Configuration 3. Source Code Management 4. Environement Control 5. Other Configuration | H8: Open
B9: 4 | C9: 4. Communication Plan & Tools | D9: PM | E9: 1. Meeting Plan 2. Communication plan 3. Comunication Tools 4. Development Tools | H9: Open
B10: 5 | C10: 5. Standard Metric | D10: PM | E10: 1. Standard metric 2. Quality metric by Stage 3. Quality Assurance Strategic 3. Non-functional requirements ensuring criteria | H10: Open
B11: 6 | C11: 6. Other Plan | D11: PM | E11: 1. Change Management 2. Risk Management​ 3. Resource Allocation Plan | F11: Chủ yếu refer các tài liệu khác | H11: Open

Sheet 1. Project Information
D1: Project Information | F1: ='0. Tasklist'!$G$1 -> Mã số: BM03-QT-OP-01
F2: ='0. Tasklist'!$G$2 -> Ngày hiệu lực: 10/09/2025
F3: ='0. Tasklist'!$G$3 -> Lần ban hành: 02
B5: Project Code | D5: P001 | F5: Project Manager | G5: DuongNH
B6: Project Name | D6: Truyenthieu | F6: Updated Date | G6: 46219
B8: 1. Project Information
B9: Project Customer | D9: Customer Code | F9: Customer Name
B10: Project Type | D10: Contract Type | E10: Fixed Price | F10: Project Type | G10: New Development
B11: Project Period | D11: Start Date | E11: 42200 | F11: End Date | G11: 42221
B12: Project Effort (Man month) | D12: Budgeted Plan | E12: 0.7 | F12: Plan Effort | G12: 0.7
B13: Project Overview | D13: Project Situation | E13: Dự án Truyenthieu (Ứng dụng web app đọc, quản lý sách online/offline) + Dự án nâng cấp Ứng dụng đọc và quản lý sách cũ trong môn 6.AI for dev trong khóa học VTI + Project Background: - Hệ thống hiện tại là một ứng dụng quản lý sách cơ bản, cho phép người dùng lưu thông tin sách và đọc PDF từ file trên thiết bị hoặc từ URL. - Tuy nhiên, PDF cục bộ hiện đang được lưu trong IndexedDB của trình duyệt. Dữ liệu này phụ thuộc vào từng trình duyệt, có thể bị mất khi xóa dữ liệu trình duyệt và không thuận tiện khi truy cập từ thiết bị khác. - Dự án này được thực hiện nhằm nâng cấp hệ thống thành một ứng dụng quản lý và đọc PDF cá nhân hoàn chỉnh ở mức cơ bản.
D14: Project Product | E14: [Project product overview: Dự án Truyenthieu sẽ cung cấp công cụ đọc sách PDF online và offline, tạo tiền đề cho phát triển thành ứng dụng đọc sách mới Product description: + Quản lý các sách có trong máy tính hoặc có nguồn PDF trên mạng + Lưu dấu trang đọc sách, tra cứu dễ dàng + Thống kê số sách + Cho phép người dùng upload PDF từ máy tính hoặc điện thoại. + Cho phép tải PDF xuống trình duyệt để đọc offline. + Cung cấp giao diện responsive cho máy tính và điện thoại.
B15: Project's Acceptance Criteria | D15: Criteria | E15: Description | F15: Acceptance Criteria
D16: 1 | F16: Code đã được triển khai.
D17: 2 | F17: Build không có lỗi.
D18: 3 | F18: Luồng bình thường hoạt động.
D19: 4 | F19: Các trường hợp lỗi chính đã được xử lý.
D20: 5 | F20: Unit Test liên quan đã pass.
D21: 6 | F21: Integration hoặc System Test liên quan đã pass.
D22: 7 | F22: Tài liệu thiết kế được cập nhật nếu code thay đổi.
B24: 2. Project Scope
B25: 2.1. Project Stage
B26: No | C26: Stage | D26: Customer | E26: Internal
B27: 1 | C27: Requirement Gathering | E27: Yes
B28: 2 | C28: System Analysis | E28: Yes
B29: 3 | C29: UI/UX Design | E29: Yes
B30: 4 | C30: Architecture Design | E30: Yes
B31: 5 | C31: Detail Design | E31: Yes
B32: 6 | C32: Coding | E32: Yes
B33: 7 | C33: Testing | E33: Yes
B34: 8 | C34: Deployment | E34: Yes
B35: 9 | C35: Maintenance | E35: Yes
B37: 2.2. Project Environment
B38: No | C38: Environment | D38: Yes/No
B39: 1 | C39: Development Environment | D39: Yes
B40: 2 | C40: Testing Environment | D40: Yes
B41: 3 | C41: Staging Environment | D41: Yes
B42: 4 | C42: Production Environment | D42: Yes
B44: 2.3. Project Technologies
B45: No | C45: Component | D45: Description
...

Sheet 2. Role & Team
D1: Role & Team | J1: ='0. Tasklist'!$G$1 -> Mã số: BM03-QT-OP-01
J2: ='0. Tasklist'!$G$2 -> Ngày hiệu lực: 10/09/2025
J3: ='0. Tasklist'!$G$3 -> Lần ban hành: 02
B5: 1. Project Roles
B6: No | C6: Role | D6: Abbreviation | E6: Type | F6: Responsibility Description
B7: 1 | C7: Project Manager | D7: PM | E7: Internal | F7: [Fill responibilities of this role]
B8: 2 | C8: Solution Architecturer | D8: SA | E8: Internal | F8: [Fill responibilities of this role]
B9: 3 | C9: Technical Leader | D9: TL | E9: Internal | F9: [Fill responibilities of this role]
B10: 4 | C10: Developer | D10: DEV | E10: Internal | F10: [Fill responibilities of this role]
B11: 5 | C11: Tester | D11: TEST | E11: Internal | F11: [Fill responibilities of this role]
B12: 6 | C12: Designer | D12: DESIGNER | E12: Internal | F12: [Fill responibilities of this role]
B13: 7 | C13: Comtor | D13: COMTOR | E13: Internal | F13: [Fill responibilities of this role]
B14: 8 | C14: Customer | D14: CUSTOMER | E14: External | F14: [Fill responibilities of this role]
B15: 9
B16: 10
B17: 11
B19: 2. Responsibility Matrix (RACI Matrix)
H20: Role
B21: No | C21: Task/Activity | D21: Stage | E21: Project Manager | F21: Solution Architecturer | G21: Technical Leader | H21: Developer | I21: Tester | J21: Designer | K21: Customer
B22: 1 | C22: Architecture Design | D22: Architecture Design | E22: A | F22: R | G22: C | H22: I | I22: I | J22: I | K22: I
B23: 2 | C23: Detail Design | D23: Detail Design | E23: A | F23: C | G23: R | H23: I | I23: I | J23: I | K23: I
B24: 3 | C24: Test Case | D24: Testing | E24: A | F24: I | G24: I | H24: I | I24: R | J24: I | K24: I
B25: 4
B26: 5
B27: 6
B28: 7
B29: 8
B30: 9
B31: 10
B33: 3. Team
B34: No | C34: Name | D34: Role | E34: Email | F34: Joined Date | G34: Released Date | H34: Phone | I34: Type
B35: 1 | C35: Nguyễn Văn A1 | D35: Project Manager | F35: 45658 | G35: 46022 | I35: Internal
B36: 2 | C36: Nguyễn Văn A2 | D36: Solution Architecturer | F36: 45658 | G36: 46022 | I36: Internal
B37: 3 | C37: Nguyễn Văn A3 | D37: Technical Leader | F37: 45658 | G37: 46022 | I37: Internal
B38: 4 | C38: Nguyễn Văn A4 | D38: Developer | F38: 45658 | G38: 46022 | I38: Internal
B39: 5 | C39: Nguyễn Văn A5 | D39: Developer | F39: 45658 | G39: 46022 | I39: Internal
B40: 6 | C40: Nguyễn Văn A6 | D40: Tester | F40: 45658 | G40: 46022 | I40: Internal
B41: 7 | C41: Nguyễn Văn A7 | D41: Tester | F41: 45658 | G41: 46022 | I41: Internal
B42: 8 | C42: Nguyễn Văn A8 | D42: Designer | F42: 45658 | G42: 46022 | I42: Internal
B43: 9 | C43: Nguyễn Văn A9 | D43: Comtor | F43: 45658 | G43: 46022 | I43: Internal
...

Sheet 3.Configuration Plan
D1: Configuration Plan | G1: ='0. Tasklist'!$G$1 -> Mã số: BM03-QT-OP-01
G2: ='0. Tasklist'!$G$2 -> Ngày hiệu lực: 10/09/2025
G3: ='0. Tasklist'!$G$3 -> Lần ban hành: 02
B6: No | C6: Folder | D6: Description | F6: Location | G6: Access Permission | H6: Location Type (Teams/NextCloud/ … ) | I6: Link
B7: =ROW()-6 -> 1 | C7: Root Folder: P001 | D7: Project in Local Computer | F7: C:\Users\ADMIN\Documents\code-work\Newwave\BrSE_Training\AI_Training\Newwave_AI_Training | H7: Local Computer
B8: =ROW()-6 -> 2 | C8: 01_Project_Planning | D8: (Project Open, Contract, Estimation) BM01, BM02 | F8: C:\Users\ADMIN\Documents\code-work\Newwave\BrSE_Training\AI_Training\Newwave_AI_Training\Project_ngan\01_Project_Management\BM03_NWS_P001_Project Management Plan_v2.0.xlsx | H8: Local Computer
B9: 3 | D9: BM05_NWS_P001_Project Schedule_v1.0_EN | F9: C:\Users\ADMIN\Documents\code-work\Newwave\BrSE_Training\AI_Training\Newwave_AI_Training\Project_ngan\01_Project_Management\BM05_NWS_P001_Project Schedule_v1.0_EN.xlsx | H9: Local Computer
B10: =ROW()-6 -> 4 | C10: Root Folder: P001 | D10: Project in Local Computer | F10: C:\Users\ADMIN\Documents\code-work\Newwave\BrSE_Training\AI_Training\Newwave_AI_Training | H10: Local Computer
B11: =ROW()-6 -> 5 | C11: 01_Project_Planning | D11: (Project management plan, schedules, risk assessments, project reports) BM01, BM03 , BM04 , BM05 | F11: C:\Users\ADMIN\Documents\code-work\Newwave\BrSE_Training\AI_Training\Newwave_AI_Training\Project_ngan\01_Project_Management | H11: Local Computer
B12: =ROW()-6 -> 6 | C12: 02_Requirements | D12: (Business and technical requirements, change requests) BM06, BM13, BM14, BM15, BM34 | F12: /[ProjectCode]/02_Requirements | G12: Read: All members Write/Modify: PM, TL Delete: PM | H12: Teams
B13: =ROW()-6 -> 7 | C13: 03_Design | D13: (Wireframes, architecture diagrams, UI/UX design, detail design) BM18, BM19, BM20, BM21, BM22, BM23 | F13: /[ProjectCode]/03_Design | G13: Read: All members Write/Modify: PM, TL, Designer Delete: PM | H13: Teams
B14: =ROW()-6 -> 8 | C14: 04_Development | D14: (Source code, scripts, database schemas) BM24 | F14: /[ProjectCode]/04_Development | G14: Read: All members Write/Modify: PM, TL, Developer Delete: PM | H14: Teams
B15: =ROW()-6 -> 9 | C15: 05_Testing | D15: (Test cases, Test results, Test report) BM26, BM27, BM28, BM29 | F15: /[ProjectCode]/05_Testing | G15: Read: All members Write/Modify: PM, TL, Tester Delete: PM | H15: Teams
B16: =ROW()-6 -> 10 | C16: 06_Deployment | D16: (Release notes, deployment scripts, rollback plans) BM30, BM31 | F16: /[ProjectCode]/06_Deployment | G16: Read: All members Write/Modify: PM, TL, Tester Delete: PM | H16: Teams
B17: =ROW()-6 -> 11 | C17: 07_Documentation | D17: (User manuals, training guides, FAQs and project templates) | F17: /[ProjectCode]/07_Documentation | G17: Read: All members Write/Modify: All members Delete: PM | H17: Teams
B18: =ROW()-6 -> 12 | C18: 08_Communication | D18: (Meeting minutes, emails, stakeholder reports) BM08 | F18: /[ProjectCode]/08_Communication | G18: Read: All members Write/Modify: PM, TL Delete: PM | H18: Teams
B19: =ROW()-6 -> 13 | C19: 09_Backups | D19: (Versioned backups, recovery plans) | F19: /[ProjectCode]/09_Backups | G19: Read: All members Write/Modify: PM, TL Delete: PM | H19: Teams
B20: =ROW()-6 -> 14 | C20: 10_CustomerSupplied | D20: (All materials provided by Customer) | F20: /[ProjectCode]/10_CustomerSupplied | G20: Read: All members Write/Modify: PM, TL, Tester, Developer Delete: PM | H20: Teams
B21: =ROW()-6 -> 15 | C21: 11_Codex/ChatGPT-support | F21: codex://threads/019f4c76-32b3-75e3-8844-0e064282e5f2 | H21: Codex App
B23: 2. File/Document Configuration
B24: No | C24: File | D24: Folder Location | F24: File Name Format | G24: Template Path | H24: Note
B25: 1 | C25: Architecture Design | D25: /[Project Code]/03_Design/AD/v[x.y]/ | F25: NWS_[ProjectCode]_AD_v[x.y] | G25: /[Project Code]/07_Documentation/Templates/NWS_AD_v1.0 | H25: x: major version, y: minor version
B26: 2 | C26: Detail Design | D26: /[Project Code]/03_Design/DD/v[x.y]/ | F26: NWS_[ProjectCode]_[FunctionID]_DD_v[x.y] | G26: /[Project Code]/07_Documentation/Templates/NWS_DD_v1.0 | H26: x: major version, y: minor version
B27: 3 | C27: Test Case | D27: /[Project Code]/05_Testing/[Stage]/[FunctionID] | F27: NWS_[ProjectCode]_[FunctionID]_TestCase_v[x.y] | G27: /[Project Code]/07_Documentation/Templates/NWS_TestCase_v1.0 | H27: x: major version, y: minor version
B28: 4 | C28: Test Result | D28: /[Project Code]/05_Testing/[Stage]/[FunctionID] | F28: NWS_[ProjectCode]_[FunctionID]_TestResult_v[x.y] | G28: /[Project Code]/07_Documentation/Templates/NWS_TestResult_v1.0 | H28: x: major version, y: minor version
B29: 5 | C29: Test Report | D29: /[Project Code]/05_Testing/[Stage]/ | F29: NWS_[ProjectCode]_[Stage]_TestReport_v[x.y] | G29: /[Project Code]/07_Documentation/Templates/NWS_TestReport_v1.0 | H29: + Stage: UT/IT/ST/UAT
B30: 6 | C30: …
B31: 7
B33: 3. Source Code Management
B34: 3.1. Branch management
B35: No | C35: Branch | D35: Description | F35: Content Format | G35: Note
B36: 1 | C36: main | D36: chứa phiên bản stable đã release.
B37: 2 | C37: branch1 | D37: chứa phiên bản app cũ
B38: 3 | C38: update/renew-app-20260713 | D38: chứa phiên bản update | G38: Được tạo bằng codex nên quy tắc đặt tên hơi bị lỏd, sẽ fix sau (ưu tiên thấp)
B39: 4 | C39: hotfix | D39: xử lý lỗi khẩn cấp. | G39: develop/[feature-id]
B40: 5
B42: 3.2. Source code management (Pull request, code review & tagging)
B43: No | C43: Activity | D43: Description | F43: Content Format | G43: Note
B44: 1 | C44: Hệ thống quản lý mã nguồn | D44: GitLab / GitHub / Bitbucket
B45: 2 | C45: Nhánh chính | D45: main, update/renew-app-20260713 (tùy Git flow)
...

Sheet 4. Communication Plan & Tools
D1: Communication Plan & Tools | H1: ='0. Tasklist'!$G$1 -> Mã số: BM03-QT-OP-01
H2: ='0. Tasklist'!$G$2 -> Ngày hiệu lực: 10/09/2025
H3: ='0. Tasklist'!$G$3 -> Lần ban hành: 02
B5: 1. Meeting Plan
B6: No | C6: Meeting Type | D6: Method | E6: Frequently | F6: Goal/Content | G6: Facilitator | H6: Time
B7: 1 | C7: Kick-off meeting | D7: Meeting | E7: Start Project | F7: TBD | G7: PM
B8: 2 | C8: Daily meeting | D8: Meeting | E8: Daily | F8: TBD | G8: PM
B9: 3 | C9: Daily report | D9: Chat (Teams) | E9: Daily | F9: TBD | G9: PM
B10: 4 | C10: Trao đổi nội bộ | D10: Chat (Teams) | E10: Real-time | F10: TBD | G10: Team
B11: 5 | C11: Grooming & Planing | D11: Meeting | E11: Start sprint | F11: TBD | G11: PM
B12: 6 | C12: Review & Retrospective | D12: Meeting | E12: End sprint | F12: TBD | G12: PM
B13: 7 | C13: Internal Demo | D13: Meeting | E13: End sprint | F13: TBD | G13: PM
B14: 8
B15: 9
B16: 10
B18: 2. Communication plan
B19: No | C19: Communication Type | D19: Method | E19: Frequently | F19: Goal/Content | G19: Facilitator | H19: Time
B20: 1 | C20: Weekly Report | D20: File | E20: Weekly | F20: TBD | G20: PM
B21: 2 | C21: Issue Report | D21: File | E21: Irregular, TBD | F21: TBD | G21: PM
B22: 3 | C22: Liên lạc | E22: Real-time | F22: TBD | G22: Team
B23: 4 | C23: Trao đổi Q&A | D23: Google Docs | E23: Real-time | F23: TBD | G23: Team
B24: 5
B25: 6
B26: 7
B27: 8
B28: 9
B29: 10
B31: 3. Comunication Tools
B32: No | C32: Tools | D32: Stage | E32: Purpose | G32: Version | H32: Security & Compliance requirements
B33: 1 | D33: All
B34: 2 | D34: All
B35: 3 | D35: All
B36: 4 | D36: All
B37: 5 | D37: All
B39: 4. Tools
B40: No | C40: Tools | D40: Stage | E40: Purpose | G40: Version | H40: Security & Compliance requirements
B41: 1 | D41: All
B42: 2 | D42: All
B43: 3 | D43: All
B44: 4 | D44: All
...

Sheet 5. Standard Metric
D1: Project Metric | H1: ='0. Tasklist'!$G$1 -> Mã số: BM03-QT-OP-01
H2: ='0. Tasklist'!$G$2 -> Ngày hiệu lực: 10/09/2025
H3: ='0. Tasklist'!$G$3 -> Lần ban hành: 02
B5: 1. Project Standard Metric
F6: Target | L6: Result tracking
B7: No | C7: Category | D7: Metric | E7: Unit | F7: LSL | G7: Average | H7: USL | I7: Objectives | J7: Formula | K7: When | L7: YYYY-MM-DD | M7: YYYY-MM-DD | N7: YYYY-MM-DD | O7: YYYY-MM-DD | P7: YYYY-MM-DD
B8: 1 | C8: Quality | D8: Customer Satisfaction | E8: Point | F8: 80 | G8: 90 | H8: 100 | I8: Đánh giá mức độ đáp ứng yêu cầu của khách hàng | J8: Tổng điểm trong phiếu khảo sát khách hàng từng lần/ kết thúc dự án | K8: Fixed Prices: Close Project Labo : 2 tuần/lần
B9: 2 | D9: Leakage | E9: No.Def/MM | F9: 0.06 | G9: 0.13 | H9: 0.2 | I9: Đo chất lượng sản phẩm/dịch vụ sau khi bàn giao (User Acceptance Test) | J9: – Số lỗi phát hiện sau bàn giao / Kích thước dự án | K9: End phase/ Close project
B10: 3 | D10: Defect rate (Coding) | E10: No.Def/MM | F10: 12 | G10: 17 | H10: 23 | I10: Đánh giá chất lượng toàn bộ sản phẩm dự án | J10: – Tổng số lỗi (Code review + Peer review+ Unit test)/ Kích thước dự án | K10: Fixed Prices: Milestone/End phase /Close project Labo: Monthly/End phase /Close project
B11: 4 | D11: Defect rate (Testing) | E11: No.Def/MM | F11: 3 | G11: 6.5 | H11: 9.7 | I11: Đánh giá chất lượng toàn bộ sản phẩm dự án | J11: – Tổng số lỗi (System Test + Integration Test + Regression Test) / Kích thước dự án | K11: Fixed Prices: Milestone/End phase /Close project Labo: Monthly/End phase /Close project
B12: 5 | C12: Cost | D12: Effort Efficiency | E12: % | F12: 80 | G12: 95 | H12: 110 | I12: Đo lường hiệu suất sử dụng nguồn lực dự án | J12: = (Plan MM / Actual effort ) * 100 | K12: Monthly/Close phase/Close project
B13: 6 | C13: Delivery | D13: Timeliness | E13: % | F13: 80 | G13: 90 | H13: 100 | I13: Đánh giá thời gian giao hàng đúng hạn | J13: = (Tổng thời gian giao đúng hạn / Tổng thời gian dự án cần giao tới khách hàng đến thời điểm báo cáo) × 100 | K13: Monthly/Close phase/Close project
B14: 7 | C14: Process | D14: Process Compliance | E14: % | F14: 80 | G14: 90 | H14: 100 | I14: Đánh giá mức độ tuân thủ chuẩn/quy trình/quy định | J14: = SUMPRODUCT(checked items,assessment results)/SUM(checked items). | K14: Labo: Monthly, Close phase/ project Fixed Prices: Milestone, Close phase/ project
B16: 2. Quality metric by Stage
F17: Target Result | L17: Result tracking
B18: No | C18: Stage | D18: Metric | E18: Description/ Calculation Formula | F18: Min value | G18: Norm value | H18: Max value | I18: Objectives | J18: Formula | K18: When | L18: YYYY-MM-DD | M18: YYYY-MM-DD | N18: YYYY-MM-DD | O18: YYYY-MM-DD | P18: YYYY-MM-DD
B19: 1 | C19: Architecture Design | D19: Comment rate for Basic Design | E19: Số comment/10 pages | F19: 2 | G19: 3 | H19: 5 | I19: Đánh giá mức độ đáp ứng yêu cầu của khách hàng cho tài liệu thiết kế kiến trúc | J19: Đếm tổng số comment được reviewer ghi chú trên tài liệu thiết kế cơ bản (Basic Design) chia theo số lượng trang (10 pages). 🔧 Tool: Word (Review → Comments), PDF Reader (Comment Summary), Google Docs (Comment Count) | K19: Fixed Prices: Milestone/End phase /Close project Labo: Monthly/End phase /Close project
B20: 2 | C20: Detail Design | D20: Comment rate for Detail Design | E20: Số comment/10 pages | F20: 3 | G20: 5 | H20: 7 | I20: Đánh giá mức độ đáp ứng yêu cầu của khách hàng cho tài liệu thiết kế chi tiết | J20: Tương tự như trên, nhưng áp dụng cho tài liệu thiết kế chi tiết (Detail Design). 🔧 Tool: Word, PDF, hoặc hệ thống DMS có lưu comment | K20: Fixed Prices: Milestone/End phase /Close project Labo: Monthly/End phase /Close project
B21: 3 | C21: Testing | D21: Bug rate for Unit Test | E21: Số comment hoặc lỗi/1000 dòng code | F21: 5 | G21: 10 | H21: 15 | I21: Đánh giá mức độ đáp ứng yêu cầu của khách hàng cho source code sau công đoạn coding | J21: Đếm số lỗi (bugs) được phát hiện trong Unit Test chia cho số lượng dòng code viết mới. 🔧 Tool: GitHub/GitLab + CLOC để tính LOC + Test result log | K21: Fixed Prices: Milestone/End phase /Close project Labo: Monthly/End phase /Close project
B22: 4 | C22: Testing | D22: Coverage rate for Unit test | E22: Tỉ lệ Coverage source code … | F22: 0.8 | G22: 0.9 | H22: 1 | I22: Đánh giá mức độ đáp ứng yêu cầu của khách hàng cho source code sau công đoạn coding | J22: Dùng công cụ đo coverage để tính số dòng code được test chia cho tổng số dòng code. 🔧 Tool: JUnit, NUnit | K22: Fixed Prices: Milestone/End phase /Close project Labo: Monthly/End phase /Close project
B23: 5 | C23: Testing | D23: Bug rate for IT Test | E23: Số bug/1000 dòng code | F23: 5 | G23: 7 | H23: 10 | I23: Đánh giá mức độ đáp ứng yêu cầu của khách hàng cho sản phẩm sau giai đoạn tích hợp hệ thống | J23: Tổng số lỗi được ghi nhận trong IT Test chia cho tổng số dòng code đôi tượng 🔧 Tool: Redmine, CLOC | K23: Fixed Prices: Milestone/End phase /Close project Labo: Monthly/End phase /Close project
B24: 6 | C24: Testing | D24: Bug rate for UAT Test | E24: Số bug/1000 dòng code | F24: 0.5 | G24: 0.7 | H24: 1 | I24: Đánh giá mức độ đáp ứng yêu cầu của khách hàng cho sản phẩm sau giai đoạn bàn giao hệ thống | J24: Tương tự trên nhưng tính lỗi trong quá trình UAT test. 🔧 Tool: Redmine, CLOC | K24: Fixed Prices: Milestone/End phase /Close project Labo: Monthly/End phase /Close project
B25: 7 | C25: Testing | D25: Bug rate for IT Test | E25: Số Bug/MM | F25: 15 | G25: 20 | H25: 25 | I25: Đánh giá mức độ đáp ứng yêu cầu của khách hàng cho sản phẩm sau giai đoạn tích hợp hệ thống | J25: Tổng số bug tìm thấy trong IT Test chia cho số MM (man-month) effort đã sử dụng. 🔧 Tool: Redmine + Resource allocation trên kênh PM | K25: Fixed Prices: Milestone/End phase /Close project Labo: Monthly/End phase /Close project
B26: 8 | C26: Testing | D26: Bug rate for UAT Test | E26: Số Bug/MM | F26: 3 | G26: 5 | H26: 7 | I26: Đánh giá mức độ đáp ứng yêu cầu của khách hàng cho sản phẩm sau giai đoạn bàn giao hệ thống | J26: Tổng số bug tìm thấy trong UAT Test chia cho số MM (man-month) effort đã sử dụng. 🔧 Tool: Redmine + Resource allocation trên kênh PM | K26: Fixed Prices: Milestone/End phase /Close project Labo: Monthly/End phase /Close project
B28: 3. Quality Assurance Strategic
B29: No | C29: Stage | D29: Activity | E29: Approach Method | F29: Description
B30: 1 | C30: Coding | D30: Coding | E30: Triển khai áp dụng tiêu chuẩn coding chuẩn | F30: Áp dụng chuẩn (ví dụ: Google Java Style, JavaScript Style Guide). Có file .editorconfig để thống nhất format.
B31: 2 | C31: Coding | D31: Code review | E31: Triển khai chạy review static source code dùng tool | F31: Chạy tự động SonarQube, ESLint khi commit/push. Rule: Cyclomatic Complexity, Code Smells, Security Vulnerabilities. Threshold: Code Smells < X, Coverage ≥ 80%.
B32: 3 | C32: Coding | D32: Code review | E32: Triển khai Leader thực hiện review code | F32: Pull Request/Checklist review bắt buộc Tối thiểu có 1 lượt cross review hoặc leader review Bắt buộc sửa comment trước khi merge Comment list tổng hợp lại trên redmine
B33: 4 | C33: Testing | D33: Unit test | E33: Triển khai thiết lập tiêu chuẩn Unit testing | F33: Tối thiểu đến cover C0/C1. Gồm cả abnormal case
B34: 5 | C34: Testing | D34: Unit test | E34: Triển khai tiêu chuẩn execute Unit testing | F34: Coverage ≥ 80% Unit Test phải chạy tự động qua CI/CD pipeline.
B35: 6 | C35: Testing | D35: Integration Test | E35: Triển khai phân tích nguyên nhân bug theo phương pháp 5Why | F35: Phân tích nguyên nhân, dùng 5Why để tìm được nguyên nhân gốc rễ Đưa ra solution Check similar Check degrade Đối ứng toàn bộ các similar và degrade
B38: 4. Non-functional requirements ensuring criteria
B39: (*)Trong trường hợp khách hàng yêu cầu
B40: No | C40: Stage | D40: Activity | E40: Approach Method | F40: Description
B41: 1 | C41: Coding | D41: Coding | E41: Performance | F41: Áp dụng các kỹ thuật cải thiện performance như : + Đánh index + Dùng store procedure + Multi-thread + Review luồng nghiệp vụ tổng quan

Sheet 6. Other plan
D1: Change Management & Risk management​ | H1: ='0. Tasklist'!$G$1 -> Mã số: BM03-QT-OP-01
H2: ='0. Tasklist'!$G$2 -> Ngày hiệu lực: 10/09/2025
H3: ='0. Tasklist'!$G$3 -> Lần ban hành: 02
B5: 1. Change Management Plan
B6: No | C6: Item | D6: Description | F6: Note
B7: 1 | C7: Change Management File | D7: Refer [BM06_NWS_[ProjectCode]_CR Management_v1.0]
B9: 2. Risk Management​ Plan
B10: No | C10: Management​ content | D10: Description | F10: Note
B11: 1 | C11: Risk Management File | D11: Refer [BM04_NWS_[ProjectCode]_Risk Management_v1.0] | F11: "C:\Users\ADMIN\Documents\code-work\Newwave\BrSE_Training\AI_Training\Newwave_AI_Training\Project_ngan\01_Project_Management\BM04_NWS_P001_Risk Management_v1.0.xlsx"
B13: 3. Resource Allocation Plan
B14: No | C14: Management​ content | D14: Description | F14: Note
B15: 1 | C15: Resource Allocation File | D15: Refer [BM12_NWS_[ProjectCode]_Resource Allocation Plan_v1.0]

Sheet Master
A1: Master Data
A2: Resposibility
A3: No | B3: Item | C3: Description | E3: No | F3: Stage
A4: 1 | B4: R | C4: Responsible (Does the work) | E4: 1 | F4: Requirement Gathering
A5: 2 | B5: A | C5: Accountable (Final approval) | E5: 2 | F5: System Analysis
A6: 3 | B6: C | C6: Consulted (Provides input) | E6: 3 | F6: UI/UX Design
A7: 4 | B7: I | C7: Informed (Kept updated) | E7: 4 | F7: Architecture Design
A8: 5 | B8: - | C8: None | E8: 5 | F8: Detail Design
E9: 6 | F9: Coding
E10: 7 | F10: Testing
E11: 8 | F11: Deployment
E12: 9 | F12: Maintenance
E13: 10 | F13: All
